<?xml version="1.0"?>
<!-- Set the robot's name -->
<robot  name="robotis_op2" xmlns:xacro="http://www.ros.org/wiki/xacro">

  <!-- <xacro:include filename="$(find thor_mang_description)/urdf/joint_params.xacro" />
  -->
  <macro name="robotis_op_arm_macro">

  <link name="MP_BACK_L">
    <inertial>
      <origin xyz="-0.0031158909 0.020443695 -0.019663084" />
      <mass value="0.010"/>
      <inertia ixx="3.1081800"  ixy="-0.25460189"  ixz="2.0318174" iyy="6.3787776" iyz="0.16417863" izz="5.3316425" />
    </inertial>
    <xacro:back_l_collision_geom_macro />
    <xacro:back_l_visual_geom_macro />
  </link>  

  <link name="MP_SHOULDER_L">
    <inertial>
      <origin xyz="-0.013522619 0.010264050 0.0013935747" />
      <mass value="0.025913024"/>
      <inertia ixx="0.0097758165"  ixy="0.0016911839"  ixz="-0.00045174329" iyx="0.0016911839" iyy="0.010511104" iyz="0.00033406955" izx="-0.00045174329" izy="0.00033406955" izz="0.005476798" />
    </inertial>  
    <xacro:shoulder_l_collision_geom_macro />
    <xacro:shoulder_l_visual_geom_macro />  
  </link>

  <link name="MP_ARM_HIGH_L" >
    <inertial>
      <origin xyz="-0.036239 0.000734 0.000660" />
      <mass value="0.16837715"/>
      <inertia ixx="0.12202839"  ixy="-0.0020812626"  ixz="-0.00088143449" iyx="-0.0020812626" iyy="0.038088441" iyz="0.0018251448" izx="-0.00088143449" izy="0.0018251448" izz="0.11340830" />
    </inertial>
    <xacro:arm_high_l_collision_geom_macro />
    <xacro:arm_high_l_visual_geom_macro />  
  </link>

  <link name="MP_ARM_LOW_L" >
    <inertial>
      <origin xyz="0.000000 0.000000 0.000000"/>
      <mass value="0.059288504"/>
      <inertia ixx="0.086855267"  ixy="0.0053020311"  ixz="0.00043636051" iyx="0.0053020311" iyy="0.021192085" iyz="-0.0064855932" izx="0.00043636051" izy="-0.0064855932" izz="0.086845450" />
    </inertial>
    <xacro:arm_low_l_collision_geom_macro />
    <xacro:arm_low_l_visual_geom_macro /> 
  </link>


 <link name="MP_ARM_GRIPPER_FIX_L" >
    <inertial>
      <origin xyz="0.045838 -0.013490 0.006666"/>
      <mass value="0.010"/>
      <inertia ixx="0.12202839"  ixy="-0.0020812626"  ixz="-0.00088143449" iyx="-0.0020812626" iyy="0.038088441" iyz="0.0018251448" izx="-0.00088143449" izy="0.0018251448" izz="0.11340830" />
    </inertial> 
    <xacro:arm_gripper_fix_l_collision_geom_macro />
    <xacro:arm_gripper_fix_l_visual_geom_macro /> 
  </link>

  <link name="MP_ARM_GRIPPER_FIX_DUMMY_L" >
    <inertial>
      <origin xyz="0 0 0"/>
      <mass value="0.010"/>
      <inertia ixx="0.12202839"  ixy="-0.0020812626"  ixz="-0.00088143449" iyx="-0.0020812626" iyy="0.038088441" iyz="0.0018251448" izx="-0.00088143449" izy="0.0018251448" izz="0.11340830" />
    </inertial> 
    <xacro:arm_gripper_fix_dummy_l_collision_geom_macro />
    <xacro:arm_gripper_fix_dummy_l_visual_geom_macro /> 
  </link>

  <link name="MP_ARM_GRIPPER_MOV_L" >
    <inertial>
      <origin xyz="0.000000 0.000000 0.000000"/>
      <mass value="0.010"/>
      <inertia ixx="0.12202839"  ixy="-0.0020812626"  ixz="-0.00088143449" iyx="-0.0020812626" iyy="0.038088441" iyz="0.0018251448" izx="-0.00088143449" izy="0.0018251448" izz="0.11340830" />
    </inertial>
    <xacro:arm_gripper_mov_l_collision_geom_macro />
    <xacro:arm_gripper_mov_l_visual_geom_macro />
  </link>

  <link name="MP_BACK_R">
    <inertial>
      <origin xyz="0 0 0" />
      <mass value="0.010"/>
      <inertia ixx="3.1081800"  ixy="-0.25460189"  ixz="2.0318174" iyy="6.3787776" iyz="0.16417863" izz="5.3316425" />
    </inertial>  
    <xacro:back_r_collision_geom_macro />
    <xacro:back_r_visual_geom_macro />   
  </link>

  <link name="MP_SHOULDER_R" >
    <inertial>
      <origin xyz="-0.013523 0.010264 0.001394" />
      <mass value="0.025913024"/>
      <inertia ixx="0.0097758165"  ixy="0.0016911839"  ixz="-0.00045174329" iyx="0.0016911839" iyy="0.010511104" iyz="0.00033406955" izx="-0.00045174329" izy="0.00033406955" izz="0.005476798" />
    </inertial>
    <xacro:shoulder_r_collision_geom_macro />
    <xacro:shoulder_r_visual_geom_macro />  
  </link>

  <link name="MP_ARM_HIGH_R" >
    <inertial>
      <origin xyz="-0.036239 0.000734 -0.000660" />
      <mass value="0.16837715"/>
      <inertia ixx="0.12202839"  ixy="-0.0020812626"  ixz="-0.00088143449" iyx="-0.0020812626" iyy="0.038088441" iyz="0.0018251448" izx="-0.00088143449" izy="0.0018251448" izz="0.11340830" />
    </inertial>
    <xacro:arm_high_r_collision_geom_macro />
    <xacro:arm_high_r_visual_geom_macro />  
  </link>

  <link name="MP_ARM_LOW_R" >
    <inertial>
      <origin xyz="0.000000 0.000000 0.000000" />
      <mass value="0.059288504"/>
      <inertia ixx="0.086855267"  ixy="0.0053020311"  ixz="0.00043636051" iyx="0.0053020311" iyy="0.021192085" iyz="-0.0064855932" izx="0.00043636051" izy="-0.0064855932" izz="0.086845450" />
    </inertial>
    <xacro:arm_low_r_collision_geom_macro />
    <xacro:arm_low_r_visual_geom_macro />
  </link>

  <link name="MP_ARM_GRIPPER_FIX_R" >
    <inertial>
      <origin xyz="0.045838 -0.013490 0.006666"/>
      <mass value="0.010"/>
      <inertia ixx="0.12202839"  ixy="-0.0020812626"  ixz="-0.00088143449" iyx="-0.0020812626" iyy="0.038088441" iyz="0.0018251448" izx="-0.00088143449" izy="0.0018251448" izz="0.11340830" />
    </inertial>
    <xacro:arm_gripper_fix_r_collision_geom_macro />
    <xacro:arm_gripper_fix_r_visual_geom_macro />
  </link>

  <link name="MP_ARM_GRIPPER_FIX_DUMMY_R" >
    <inertial>
      <origin xyz="0 0 0"/>
      <mass value="0.010"/>
      <inertia ixx="0.12202839"  ixy="-0.0020812626"  ixz="-0.00088143449" iyx="-0.0020812626" iyy="0.038088441" iyz="0.0018251448" izx="-0.00088143449" izy="0.0018251448" izz="0.11340830" />
    </inertial> 
    <xacro:arm_gripper_fix_dummy_r_collision_geom_macro />
    <xacro:arm_gripper_fix_dummy_r_visual_geom_macro />
  </link>

  <link name="MP_ARM_GRIPPER_MOV_R" >
    <inertial>
      <origin xyz="0.000000 0.000000 0.000000"/>
      <mass value="0.010"/>
      <inertia ixx="0.12202839"  ixy="-0.0020812626"  ixz="-0.00088143449" iyx="-0.0020812626" iyy="0.038088441" iyz="0.0018251448" izx="-0.00088143449" izy="0.0018251448" izz="0.11340830" />
    </inertial>
    <xacro:arm_gripper_mov_r_collision_geom_macro />
    <xacro:arm_gripper_mov_r_visual_geom_macro />
  </link>


  <joint name="j_back_l" type="fixed">
    <parent link="MP_BODY"/>
    <child link="MP_BACK_L"/>
    <origin xyz="0 0.06035 0" rpy="-1.5707963 0 0" />
    <limit effort="2.8" velocity="5.6548668" lower="-2.6179939" upper="2.6179939" />
  </joint>

  <joint name="j_shoulder_l" type="revolute">
    <parent link="MP_BACK_L"/>
    <child link="MP_SHOULDER_L"/>
    <origin xyz="0 0 0" rpy="0 0 -1.5707963" />
    <axis xyz="0 0 1" />
    <limit effort="2.8" velocity="5.6548668" lower="-2.6179939" upper="2.6179939" />
  </joint>

  <joint name="j_high_arm_l" type="revolute">
    <parent link="MP_SHOULDER_L"/>
    <child link="MP_ARM_HIGH_L"/>
    <origin xyz="-0.016 0 0.02165" rpy="1.5707963 0.78539815 0" />
    <axis xyz="0 0 1" />
    <limit effort="2.8" velocity="5.648668" lower="-2.6179939" upper="2.6179939" />
  </joint>

  <joint name="j_low_arm_l" type="revolute">
    <parent link="MP_ARM_HIGH_L"/>
    <child link="MP_ARM_LOW_L"/>
    <origin xyz="-0.06 0 -0.016" rpy="-1.5707963 1.5707963 0" />
    <axis xyz="0 0 1" />
    <limit effort="2.8" velocity="5.6548668" lower="-2.6179939" upper="2.6179939" />
  </joint>

  <joint name="j_wrist_l" type="revolute">
    <parent link="MP_ARM_LOW_L"/>
    <child link="MP_ARM_GRIPPER_FIX_L"/>
    <origin xyz="0.048 0.016 0" rpy="1.5707963 0 0" />
    <axis xyz="0 0 1" />
    <limit effort="2.8" velocity="5.6548668" lower="-2.6179939" upper="2.6179939" />
  </joint>

  <joint name="j_wrist_dummy_l" type="fixed">
    <parent link="MP_ARM_GRIPPER_FIX_L"/>
    <child link="MP_ARM_GRIPPER_FIX_DUMMY_L"/>
    <origin xyz="0.064 -0.01 0" rpy="0 0 0" />
  </joint>

  <joint name="j_gripper_l" type="revolute">
    <parent link="MP_ARM_GRIPPER_FIX_L"/>
    <child link="MP_ARM_GRIPPER_MOV_L"/>
    <origin xyz="0.048 0.01 0" rpy="0 0 0" />
    <axis xyz="0 0 1" />
    <limit effort="2.8" velocity="5.6548668" lower="-2.6179939" upper="2.6179939" />
  </joint>

  <joint name="j_back_r" type="fixed">
    <parent link="MP_BODY"/>
    <child link="MP_BACK_R"/>
    <origin xyz="0 -0.06035 0" rpy="1.5707963 0 0" />
    <limit effort="2.8" velocity="5.6548668" lower="-2.6179939" upper="2.6179939" />
  </joint>

  <joint name="j_shoulder_r" type="revolute">
    <parent link="MP_BACK_R"/>
    <child link="MP_SHOULDER_R"/>
    <origin xyz="0 0 0" rpy="0 0 1.5707963" />
    <axis xyz="0 0 1" />
    <limit effort="2.8" velocity="5.6548668" lower="-2.6179939" upper="2.6179939" />
  </joint>

  <joint name="j_high_arm_r" type="revolute">
    <parent link="MP_SHOULDER_R"/>
    <child link="MP_ARM_HIGH_R"/>
    <origin xyz="-0.016 0 0.02165" rpy="-1.5707963 0.78539815 0" />
    <axis xyz="0 0 1" />
    <limit effort="2.8" velocity="5.648668" lower="-2.6179939" upper="2.6179939" />
  </joint>

  <joint name="j_low_arm_r" type="revolute">
    <parent link="MP_ARM_HIGH_R"/>
    <child link="MP_ARM_LOW_R"/>
    <origin xyz="-0.06 0 -0.016" rpy="1.5707963 1.5707963 0" />
    <axis xyz="0 0 1" />
    <limit effort="2.8" velocity="5.6548668" lower="-2.6179939" upper="2.6179939" />
  </joint>

  <joint name="j_wrist_r" type="revolute">
    <parent link="MP_ARM_LOW_R"/>
    <child link="MP_ARM_GRIPPER_FIX_R"/>
    <origin xyz="0.048 -0.016 0" rpy="1.5707963 0 0" />
    <axis xyz="0 0 1" />
    <limit effort="2.8" velocity="5.6548668" lower="-2.6179939" upper="2.6179939" />
  </joint>

  <joint name="j_wrist_dummy_r" type="fixed">
    <parent link="MP_ARM_GRIPPER_FIX_R"/>
    <child link="MP_ARM_GRIPPER_FIX_DUMMY_R"/>
    <origin xyz="0.064 -0.01 0" rpy="0 0 0" />
  </joint>

  <joint name="j_gripper_r" type="revolute">
    <parent link="MP_ARM_GRIPPER_FIX_R"/>
    <child link="MP_ARM_GRIPPER_MOV_R"/>
    <origin xyz="0.048 0.01 0" rpy="0 0 0" />
    <axis xyz="0 0 1" />
    <limit effort="2.8" velocity="5.6548668" lower="-2.6179939" upper="2.6179939" />
  </joint>

  <joint_transmission_macro joint_name="j_shoulder_l"/>
  <joint_transmission_macro joint_name="j_high_arm_l"/>
  <joint_transmission_macro joint_name="j_low_arm_l"/>
  <joint_transmission_macro joint_name="j_wrist_l"/>
  <joint_transmission_macro joint_name="j_gripper_l"/>

  <joint_transmission_macro joint_name="j_shoulder_r"/>
  <joint_transmission_macro joint_name="j_high_arm_r"/>
  <joint_transmission_macro joint_name="j_low_arm_r"/>
  <joint_transmission_macro joint_name="j_wrist_r"/>
  <joint_transmission_macro joint_name="j_gripper_r"/>



  </macro>
</robot>
