<?xml version="1.0"?>

<robot  name="robotis_op2" xmlns:xacro="http://www.ros.org/wiki/xacro">

  <xacro:include filename="$(find robotis_op_description)/urdf/helper_macros.urdf.xacro.xml" />
  

  <macro name="robotis_op_head_macro">

  <link name="MP_NECK">
    <inertial>
      <origin xyz="0.001424 -0.016567 -0.007128" />
      <mass value="0.024357719"/>
     <inertia ixx="0.0051411124"  ixy="-0.00057530255"  ixz="-0.000024729049" iyy="0.0081915737" iyz="-0.000019223094" izz="0.0011379812" />
    </inertial>
    <collision>
      <geometry>
        <mesh filename="package://robotis_op_description/meshes/neck_coll.stl"  scale="1 1 1"/>
      </geometry>
    </collision>
  </link>

  <link name="MP_HEAD">
    <inertial>
      <origin xyz="0.000064 -0.018565 -0.007667" />
      <mass value="0.15804192"/>
     <inertia ixx="0.1239683"  ixy="0.000078494368"  ixz="0.000007645979" iyy="0.11783781" iyz="0.0012199205" izz="0.1583601" />
    </inertial>
    <collision>
      <geometry>
        <mesh filename="package://robotis_op_description/meshes/head_coll.stl"  scale="1 1 1"/>
      </geometry>
    </collision>
  </link>

 <link name="MP_PMDCAMBOARD" >
  </link>
    <joint name="j_camboard" type="fixed">
  <parent link="MP_HEAD"/>
  <child link="MP_PMDCAMBOARD"/>
  <origin xyz="0 0 0.0235" rpy="3.14159 1.5707963 0" />
  <axis xyz="0 0 1" />
  <limit effort="2.8" velocity="5.6548668" lower="-2.6179939" upper="2.6179939" />
  </joint>

  <joint name="j_pan" type="revolute">
    <parent link="MP_BODY"/>
    <child link="MP_NECK"/>
    <origin xyz="0 0 0.0235" rpy="0 0 1.5707963" />
    <axis xyz="0 0 1" />
    <limit effort="2.8" velocity="5.6548668" lower="-2.6179939" upper="2.6179939" />
  </joint>

  <joint name="j_tilt" type="revolute">
    <parent link="MP_NECK"/>
    <child link="MP_HEAD"/>
    <origin xyz="0 0 0.02715" rpy="-1.5707963 0 1.5707963" />
    <axis xyz="0 0 1" />
    <limit effort="2.8" velocity="5.6548668" lower="-2.6179939" upper="2.6179939" />
  </joint>



  <xacro:joint_transmission_macro joint_name="j_pan"/>
  <xacro:joint_transmission_macro joint_name="j_tilt"/>

  </macro>
</robot>

