<?xml version="1.0"?>
<!-- Set the robot's name -->
<robot  name="robotis_op2" xmlns:xacro="http://www.ros.org/wiki/xacro">

  <macro name="robotis_op_leg_macro">


 <link name="MP_PELVIS_L" >
    <xacro:inertial_cuboid__with_pose_macro mass="0.197" x_length="0.025" y_length="0.045" z_length="0.032" >
      <origin xyz="0.0 0.0 0.016" />
    </xacro:inertial_cuboid__with_pose_macro>
    <pelvis_l_collision_geom_macro />
    <pelvis_l_visual_geom_macro />
  </link>

  <link name="MP_THIGH1_L" >
    <xacro:inertial_cuboid__with_pose_macro mass="0.11904336" x_length="0.028652" y_length="0.045" z_length="0.08175" >
      <origin xyz="0.000079 0.018242 0.013873" />
    </xacro:inertial_cuboid__with_pose_macro>
    <thigh1_l_collision_geom_macro />
    <thigh1_l_visual_geom_macro />
  </link>

  <link name="MP_THIGH2_L" >
    <xacro:inertial_cuboid__with_pose_macro mass="0.11904336" x_length="0.093" y_length="0.035" z_length="0.045" >
      <origin xyz="-0.062965 -0.000323 0.000692" />
    </xacro:inertial_cuboid__with_pose_macro>
    <thigh2_l_collision_geom_macro />
    <thigh2_l_visual_geom_macro />
  </link>

  <link name="MP_TIBIA_L" >
    <xacro:inertial_cuboid__with_pose_macro mass="0.0070309794" x_length="0.093" y_length="0.035" z_length="0.045" >
      <origin xyz="-0.053955 0.006548 -0.000592" />
    </xacro:inertial_cuboid__with_pose_macro>
    <tibia_l_collision_geom_macro />
    <tibia_l_visual_geom_macro />
  </link>

  <link name="MP_ANKLE1_L" >
    <xacro:inertial_cuboid__with_pose_macro mass="0.16710792" x_length="0.038652" y_length="0.07175" z_length="0.035" >
      <origin xyz="0.01 -0.025 0.0" />
    </xacro:inertial_cuboid__with_pose_macro>
    <ankle1_l_collision_geom_macro />
    <ankle1_l_visual_geom_macro />
  </link>

  <link name="MP_ANKLE2_L" >
    <xacro:inertial_cuboid__with_pose_macro mass="0.0794462" x_length="0.008" y_length="0.066" z_length="0.104" >
      <origin xyz="-0.025995 -0.009506 -0.000503" />
    </xacro:inertial_cuboid__with_pose_macro>
    <ankle2_l_collision_geom_macro />
    <ankle2_l_visual_geom_macro />
  </link>

  <link name="MP_PELVIS_R" >
    <xacro:inertial_cuboid__with_pose_macro mass="0.197" x_length="0.025" y_length="0.045" z_length="0.032" >
      <origin xyz="0.0 0.0 0.016" />
    </xacro:inertial_cuboid__with_pose_macro>
    <pelvis_r_collision_geom_macro />
    <pelvis_r_visual_geom_macro />
  </link>

  <link name="MP_THIGH1_R" >
    <xacro:inertial_cuboid__with_pose_macro mass="0.11904336" x_length="0.028652" y_length="0.045" z_length="0.08175" >
      <origin xyz="0.000079 -0.018242 0.013873" />
    </xacro:inertial_cuboid__with_pose_macro>
    <thigh1_r_collision_geom_macro />
    <thigh1_r_visual_geom_macro />
  </link>

  <link name="MP_THIGH2_R" >
    <xacro:inertial_cuboid__with_pose_macro mass="0.11904336" x_length="0.093" y_length="0.035" z_length="0.045" >
      <origin xyz="0.062965 -0.000323 0.000692" />
    </xacro:inertial_cuboid__with_pose_macro>
    <thigh2_r_collision_geom_macro />
    <thigh2_r_visual_geom_macro />
  </link>

  <link name="MP_TIBIA_R" >
    <xacro:inertial_cuboid__with_pose_macro mass="0.070309794" x_length="0.093" y_length="0.035" z_length="0.045" >
      <origin xyz="0.053955 0.006548 -0.000592" />
    </xacro:inertial_cuboid__with_pose_macro>
    <tibia_r_collision_geom_macro />
    <tibia_r_visual_geom_macro />
  </link>

  <link name="MP_ANKLE1_R" >
    <xacro:inertial_cuboid__with_pose_macro mass="0.16710792" x_length="0.038652" y_length="0.07175" z_length="0.035" >
      <origin xyz="-0.01 -0.025 0.0" />
    </xacro:inertial_cuboid__with_pose_macro>
    <ankle1_r_collision_geom_macro />
    <ankle1_r_visual_geom_macro />
  </link>

  <link name="MP_ANKLE2_R" >
    <xacro:inertial_cuboid__with_pose_macro mass="0.0794462" x_length="0.008" y_length="0.066" z_length="0.104" >
      <origin xyz="0.025995 -0.009506 -0.000503" />
    </xacro:inertial_cuboid__with_pose_macro>
    <ankle2_r_collision_geom_macro />
    <ankle2_r_visual_geom_macro />
  </link>
  
 
  



  <joint name="j_pelvis_l" type="revolute">
    <parent link="MP_BODY"/>
    <child link="MP_PELVIS_L"/>
    <origin xyz="-0.005 0.037 -0.09355" rpy="0 3.14159 -1.5707963" />
    <axis xyz="0 0 1" />
    <limit effort="6.2" velocity="5.6548668" lower="-2.6179939" upper="2.6179939" />
  </joint>

  <joint name="j_thigh1_l" type="revolute">
    <parent link="MP_PELVIS_L"/>
    <child link="MP_THIGH1_L"/>
    <origin xyz="0 0 0.028652" rpy="1.5707963 0 0" />
    <axis xyz="0 0 1" />
    <limit effort="6.2" velocity="5.6548668" lower="-2.6179939" upper="2.6179939" />
  </joint>

  <joint name="j_thigh2_l" type="revolute">
    <parent link="MP_THIGH1_L"/>
    <child link="MP_THIGH2_L"/>
    <origin xyz="0 0 0" rpy="1.5707963 0 -1.5707963" />
    <axis xyz="0 0 1" />
    <limit effort="6.2" velocity="5.6548668" lower="-2.6179939" upper="2.6179939" />
  </joint>

  <joint name="j_tibia_l" type="revolute">
    <parent link="MP_THIGH2_L"/>
    <child link="MP_TIBIA_L"/>
    <origin xyz="-0.093 0 0" rpy="0 0 0" />
    <axis xyz="0 0 1" />
    <limit effort="6.2" velocity="5.6548668" lower="-2.6179939" upper="2.6179939" />
  </joint>

  <joint name="j_ankle1_l" type="revolute">
    <parent link="MP_TIBIA_L"/>
    <child link="MP_ANKLE1_L"/>
    <origin xyz="-0.093 0 0" rpy="3.14159 0 0" />
    <axis xyz="0 0 1" />
    <limit effort="6.2" velocity="5.6548668" lower="-2.6179939" upper="2.6179939" />
  </joint>

  <joint name="j_ankle2_l" type="revolute">
    <parent link="MP_ANKLE1_L"/>
    <child link="MP_ANKLE2_L"/>
    <origin xyz="0 0 0" rpy="-1.5707963 0 0" />
    <axis xyz="0 0 1" />
    <limit effort="6.2" velocity="5.6548668" lower="-2.6179939" upper="2.6179939" />
  </joint>

  <joint name="j_pelvis_r" type="revolute">
    <parent link="MP_BODY"/>
    <child link="MP_PELVIS_R"/>
    <origin xyz="-0.005 -0.037 -0.09355" rpy="0 3.14159 1.5707963" />
    <axis xyz="0 0 1" />
    <limit effort="6.2" velocity="5.6548668" lower="-2.6179939" upper="2.6179939" />
  </joint>

  <joint name="j_thigh1_r" type="revolute">
    <parent link="MP_PELVIS_R"/>
    <child link="MP_THIGH1_R"/>
    <origin xyz="0 0 0.028652" rpy="-1.5707963 0 0" />
    <axis xyz="0 0 1" />
    <limit effort="6.2" velocity="5.6548668" lower="-2.6179939" upper="2.6179939" />
  </joint>

  <joint name="j_thigh2_r" type="revolute">
    <parent link="MP_THIGH1_R"/>
    <child link="MP_THIGH2_R"/>
    <origin xyz="0 0 0" rpy="1.5707963 0 -1.5707963" />
    <axis xyz="0 0 1" />
    <limit effort="6.2" velocity="5.6548668" lower="-2.6179939" upper="2.6179939" />
  </joint>

  <joint name="j_tibia_r" type="revolute">
    <parent link="MP_THIGH2_R"/>
    <child link="MP_TIBIA_R"/>
    <origin xyz="0.093 0 0" rpy="0 0 0" />
    <axis xyz="0 0 1" />
    <limit effort="6.2" velocity="5.6548668" lower="-2.6179939" upper="2.6179939" />
  </joint>

  <joint name="j_ankle1_r" type="revolute">
    <parent link="MP_TIBIA_R"/>
    <child link="MP_ANKLE1_R"/>
    <origin xyz="0.093 0 0" rpy="3.14159 0 0" />
    <axis xyz="0 0 1" />
    <limit effort="6.2" velocity="5.6548668" lower="-2.6179939" upper="2.6179939" />
  </joint>

  <joint name="j_ankle2_r" type="revolute">
    <parent link="MP_ANKLE1_R"/>
    <child link="MP_ANKLE2_R"/>
    <origin xyz="0 0 0" rpy="-1.5707963 0 0" />
    <axis xyz="0 0 1" />
    <limit effort="6.2" velocity="5.6548668" lower="-2.6179939" upper="2.6179939" />
  </joint>



  <joint_transmission_macro joint_name="j_pelvis_l"/>
  <joint_transmission_macro joint_name="j_thigh1_l"/>
  <joint_transmission_macro joint_name="j_thigh2_l"/>
  <joint_transmission_macro joint_name="j_tibia_l"/>
  <joint_transmission_macro joint_name="j_ankle1_l"/>
  <joint_transmission_macro joint_name="j_ankle2_l"/> 

  <joint_transmission_macro joint_name="j_pelvis_r"/>
  <joint_transmission_macro joint_name="j_thigh1_r"/>
  <joint_transmission_macro joint_name="j_thigh2_r"/>
  <joint_transmission_macro joint_name="j_tibia_r"/>
  <joint_transmission_macro joint_name="j_ankle1_r"/>
  <joint_transmission_macro joint_name="j_ankle2_r"/>

<gazebo reference="MP_ANKLE2_L">
    
    
    <material>Gazebo/White</material>    

    <mu1>9000</mu1>
    <mu2>9000</mu2>
    <kp>10000.0</kp>
    <kd>1000.0</kd>
    <minDepth>0.0000001</minDepth>
    <maxContacts>100</maxContacts>    
  </gazebo>





<gazebo reference="MP_ANKLE2_R">
    
    
    <material>Gazebo/White</material>
    

    <mu1>9000</mu1>
    <mu2>9000</mu2>
    <kp>10000.0</kp>
    <kd>1000.0</kd>
    <minDepth>0.0000001</minDepth>
    <maxContacts>100</maxContacts>    
  </gazebo>

  </macro>
</robot>

